1) POST /auth/test-session-flow (crear sesi¾n de prueba)
Traceback (most recent call last):
  File "C:\Users\danig\Documentos\GitHub\HuertoRentable\.venv\Lib\site-packages\urllib3\connection.py", line 198, in _new_conn
    sock = connection.create_connection(
        (self._dns_host, self.port),
    ...<2 lines>...
        socket_options=self.socket_options,
    )
  File "C:\Users\danig\Documentos\GitHub\HuertoRentable\.venv\Lib\site-packages\urllib3\util\connection.py", line 85, in create_connection
    raise err
  File "C:\Users\danig\Documentos\GitHub\HuertoRentable\.venv\Lib\site-packages\urllib3\util\connection.py", line 73, in create_connection
    sock.connect(sa)
    ~~~~~~~~~~~~^^^^
ConnectionRefusedError: [WinError 10061] No se puede establecer una conexi¾n ya que el equipo de destino deneg¾ expresamente dicha conexi¾n

The above exception was the direct cause of the following exception:

Traceback (most recent call last):
  File "C:\Users\danig\Documentos\GitHub\HuertoRentable\.venv\Lib\site-packages\urllib3\connectionpool.py", line 787, in urlopen
    response = self._make_request(
        conn,
    ...<10 lines>...
        **response_kw,
    )
  File "C:\Users\danig\Documentos\GitHub\HuertoRentable\.venv\Lib\site-packages\urllib3\connectionpool.py", line 493, in _make_request
    conn.request(
    ~~~~~~~~~~~~^
        method,
        ^^^^^^^
    ...<6 lines>...
        enforce_content_length=enforce_content_length,
        ^^^^^^^^^^^^^^^^^^^^^^^^^^^^^^^^^^^^^^^^^^^^^^
    )
    ^
  File "C:\Users\danig\Documentos\GitHub\HuertoRentable\.venv\Lib\site-packages\urllib3\connection.py", line 494, in request
    self.endheaders()
    ~~~~~~~~~~~~~~~^^
  File "C:\Python313\Lib\http\client.py", line 1333, in endheaders
    self._send_output(message_body, encode_chunked=encode_chunked)
    ~~~~~~~~~~~~~~~~~^^^^^^^^^^^^^^^^^^^^^^^^^^^^^^^^^^^^^^^^^^^^^
  File "C:\Python313\Lib\http\client.py", line 1093, in _send_output
    self.send(msg)
    ~~~~~~~~~^^^^^
  File "C:\Python313\Lib\http\client.py", line 1037, in send
    self.connect()
    ~~~~~~~~~~~~^^
  File "C:\Users\danig\Documentos\GitHub\HuertoRentable\.venv\Lib\site-packages\urllib3\connection.py", line 325, in connect
    self.sock = self._new_conn()
                ~~~~~~~~~~~~~~^^
  File "C:\Users\danig\Documentos\GitHub\HuertoRentable\.venv\Lib\site-packages\urllib3\connection.py", line 213, in _new_conn
    raise NewConnectionError(
        self, f"Failed to establish a new connection: {e}"
    ) from e
urllib3.exceptions.NewConnectionError: <urllib3.connection.HTTPConnection object at 0x000001FE50867E00>: Failed to establish a new connection: [WinError 10061] No se puede establecer una conexi¾n ya que el equipo de destino deneg¾ expresamente dicha conexi¾n

The above exception was the direct cause of the following exception:

Traceback (most recent call last):
  File "C:\Users\danig\Documentos\GitHub\HuertoRentable\.venv\Lib\site-packages\requests\adapters.py", line 644, in send
    resp = conn.urlopen(
        method=request.method,
    ...<9 lines>...
        chunked=chunked,
    )
  File "C:\Users\danig\Documentos\GitHub\HuertoRentable\.venv\Lib\site-packages\urllib3\connectionpool.py", line 841, in urlopen
    retries = retries.increment(
        method, url, error=new_e, _pool=self, _stacktrace=sys.exc_info()[2]
    )
  File "C:\Users\danig\Documentos\GitHub\HuertoRentable\.venv\Lib\site-packages\urllib3\util\retry.py", line 519, in increment
    raise MaxRetryError(_pool, url, reason) from reason  # type: ignore[arg-type]
    ^^^^^^^^^^^^^^^^^^^^^^^^^^^^^^^^^^^^^^^^^^^^^^^^^^^
urllib3.exceptions.MaxRetryError: HTTPConnectionPool(host='127.0.0.1', port=5000): Max retries exceeded with url: /auth/test-session-flow (Caused by NewConnectionError('<urllib3.connection.HTTPConnection object at 0x000001FE50867E00>: Failed to establish a new connection: [WinError 10061] No se puede establecer una conexi¾n ya que el equipo de destino deneg¾ expresamente dicha conexi¾n'))

During handling of the above exception, another exception occurred:

Traceback (most recent call last):
  File "C:\Users\danig\Documentos\GitHub\HuertoRentable\scripts\e2e_crops_test.py", line 7, in <module>
    r = s.post(f'{BASE}/auth/test-session-flow', json={'run':'yes'})
  File "C:\Users\danig\Documentos\GitHub\HuertoRentable\.venv\Lib\site-packages\requests\sessions.py", line 637, in post
    return self.request("POST", url, data=data, json=json, **kwargs)
           ~~~~~~~~~~~~^^^^^^^^^^^^^^^^^^^^^^^^^^^^^^^^^^^^^^^^^^^^^
  File "C:\Users\danig\Documentos\GitHub\HuertoRentable\.venv\Lib\site-packages\requests\sessions.py", line 589, in request
    resp = self.send(prep, **send_kwargs)
  File "C:\Users\danig\Documentos\GitHub\HuertoRentable\.venv\Lib\site-packages\requests\sessions.py", line 703, in send
    r = adapter.send(request, **kwargs)
  File "C:\Users\danig\Documentos\GitHub\HuertoRentable\.venv\Lib\site-packages\requests\adapters.py", line 677, in send
    raise ConnectionError(e, request=request)
requests.exceptions.ConnectionError: HTTPConnectionPool(host='127.0.0.1', port=5000): Max retries exceeded with url: /auth/test-session-flow (Caused by NewConnectionError('<urllib3.connection.HTTPConnection object at 0x000001FE50867E00>: Failed to establish a new connection: [WinError 10061] No se puede establecer una conexi¾n ya que el equipo de destino deneg¾ expresamente dicha conexi¾n'))
